<?xml version="1.0" ?>
<sdf version="1.5">
    <world name="default">

        <!-- A global light source -->
        <include>
            <uri>model://sun</uri>
        </include>

        <!-- A ground plane -->
        <include>
            <uri>model://ground_plane</uri>
        </include>
        <model name="my_robot">
            <link name='chassis'>
                <pose>0 0 .1 0 0 0</pose>

                <collision name='collision'>
                    <geometry>
                        <box>
                            <size>.4 .2 .1</size>
                        </box>
                    </geometry>
                </collision>

                <visual name='visual'>
                    <geometry>
                        <box>
                            <size>.4 .2 .1</size>
                        </box>
                    </geometry>
                </visual>
            </link>

            <link name="base_cylinder">

                <!-- Offset the base by half the lenght of the cylinder -->
                <pose>0 0 0.179335 0 0 0</pose>
                <collision name="base_cylinder_collision">
                    <geometry>
                        <cylinder>
                            <!-- Radius and length provided by Velodyne -->
                            <radius>.04267</radius>
                            <length>.05867</length>
                        </cylinder>
                    </geometry>
                </collision>

                <!-- The visual is mostly a copy of the collision -->
                <visual name="base_cylinder_visual">
                    <geometry>
                        <cylinder>
                            <radius>.04267</radius>
                            <length>.05867</length>
                        </cylinder>
                    </geometry>
                </visual>
            </link>

            <joint type="fixed" name="base_cylinder_joint">
                <pose>0 0 -0.029335 0 0 0</pose>
                <child>base_cylinder</child>
                <parent>chassis</parent>
            </joint>

            <link name="top">
                <sensor type="ray" name="sensor">

                    <!-- Position the ray sensor based on the specification. Also rotate
       it by 90 degrees around the X-axis so that the <horizontal> rays
       become vertical -->
                    <pose>0 0 -0.004645 1.5707 0 0</pose>

                    <!-- Enable visualization to see the rays in the GUI -->
                    <visualize>true</visualize>

                    <!-- Set the update rate of the sensor -->
                    <update_rate>30</update_rate>
                    <ray>

                        <!-- The scan element contains the horizontal and vertical beams.
       We are leaving out the vertical beams for this tutorial. -->
                        <scan>

                            <!-- The horizontal beams -->
                            <horizontal>
                                <!-- The velodyne has 32 beams(samples) -->
                                <samples>32</samples>

                                <!-- Resolution is multiplied by samples to determine number of
           simulated beams vs interpolated beams. See: http://sdformat.org/spec?ver=1.6&elem=sensor#horizontal_resolution
           -->
                                <resolution>1</resolution>

                                <!-- Minimum angle in radians -->
                                <min_angle>-0.53529248</min_angle>

                                <!-- Maximum angle in radians -->
                                <max_angle>0.18622663</max_angle>
                            </horizontal>
                        </scan>

                        <!-- Range defines characteristics of an individual beam -->
                        <range>

                            <!-- Minimum distance of the beam -->
                            <min>0.05</min>

                            <!-- Maximum distance of the beam -->
                            <max>70</max>

                            <!-- Linear resolution of the beam -->
                            <resolution>0.02</resolution>
                        </range>
                    </ray>
                </sensor>
                <pose>0 0 0.245455 0 0 0</pose>
                <inertial>
                    <mass>0.1</mass>
                    <inertia>
                        <ixx>0.000090623</ixx>
                        <iyy>0.000090623</iyy>
                        <izz>0.000091036</izz>
                        <ixy>0</ixy>
                        <ixz>0</ixz>
                        <iyz>0</iyz>
                    </inertia>
                </inertial>
                <collision name="top_collision">
                    <geometry>
                        <cylinder>
                            <!-- Radius and length provided by Velodyne -->
                            <radius>0.04267</radius>
                            <length>0.07357</length>
                        </cylinder>
                    </geometry>
                </collision>

                <!-- The visual is mostly a copy of the collision -->
                <visual name="top_visual">
                    <geometry>
                        <cylinder>
                            <radius>0.04267</radius>
                            <length>0.07357</length>
                        </cylinder>
                    </geometry>
                </visual>
            </link>
            <joint type="revolute" name="top_cylinder_joint">

                <!-- Position the joint at the bottom of the top link -->
                <pose>0 0 -0.036785 0 0 0</pose>

                <!-- Use the base link as the parent of the joint -->
                <parent>base_cylinder</parent>

                <!-- Use the top link as the child of the joint -->
                <child>top</child>

                <!-- The axis defines the joint's degree of freedom -->
                <axis>

                    <!-- Revolve around the z-axis -->
                    <xyz>0 0 1</xyz>

                    <!-- Limit refers to the range of motion of the joint -->
                    <limit>

                        <!-- Use a very large number to indicate a continuous revolution -->
                        <lower>-10000000000000000</lower>
                        <upper>10000000000000000</upper>
                    </limit>
                </axis>
            </joint>


            <link name="left_front_wheel">
                <pose>0.1 0.13 0.1 0 1.5707 1.5707</pose>
                <collision name="left_front_wheel_collision">
                    <geometry>
                        <cylinder>
                            <radius>.1</radius>
                            <length>.05</length>
                        </cylinder>
                    </geometry>
                </collision>
                <visual name="left_front_wheel_visual">
                    <geometry>
                        <cylinder>
                            <radius>.1</radius>
                            <length>.05</length>
                        </cylinder>
                    </geometry>
                </visual>
            </link>
            <link name="right_front_wheel">
                <pose>0.1 -0.13 0.1 0 1.5707 1.5707</pose>
                <collision name="right_front_wheel_collision">
                    <geometry>
                        <cylinder>
                            <radius>.1</radius>
                            <length>.05</length>
                        </cylinder>
                    </geometry>
                </collision>
                <visual name="right_front_wheel_visual">
                    <geometry>
                        <cylinder>
                            <radius>.1</radius>
                            <length>.05</length>
                        </cylinder>
                    </geometry>
                </visual>
            </link>
            <joint type="revolute" name="left_front_wheel_hinge">
                <pose>0 0 -0.03 0 0 0</pose>
                <child>left_front_wheel</child>
                <parent>chassis</parent>
                <axis>
                    <xyz>0 0 1</xyz>
                </axis>
            </joint>

            <joint type="revolute" name="right_front_wheel_hinge">
                <pose>0 0 0.03 0 0 0</pose>
                <child>right_front_wheel</child>
                <parent>chassis</parent>
                <axis>
                    <xyz>0 0 1</xyz>
                </axis>
            </joint>

            <link name="left_back_wheel">
                <pose>-0.15 0.13 0.1 0 1.5707 1.5707</pose>
                <collision name="left_back_wheel_collision">
                    <geometry>
                        <cylinder>
                            <radius>.1</radius>
                            <length>.05</length>
                        </cylinder>
                    </geometry>
                </collision>
                <visual name="left_back_wheel_visual">
                    <geometry>
                        <cylinder>
                            <radius>.1</radius>
                            <length>.05</length>
                        </cylinder>
                    </geometry>
                </visual>
            </link>
            <link name="right_back_wheel">
                <pose>-0.15 -0.13 0.1 0 1.5707 1.5707</pose>
                <collision name="right_front_wheel_collision">
                    <geometry>
                        <cylinder>
                            <radius>.1</radius>
                            <length>.05</length>
                        </cylinder>
                    </geometry>
                </collision>
                <visual name="right_back_wheel_visual">
                    <geometry>
                        <cylinder>
                            <radius>.1</radius>
                            <length>.05</length>
                        </cylinder>
                    </geometry>
                </visual>
            </link>
            <joint type="revolute" name="left_back_wheel_hinge">
                <pose>0 0 -0.03 0 0 0</pose>
                <child>left_back_wheel</child>
                <parent>chassis</parent>
                <axis>
                    <xyz>0 0 1</xyz>
                </axis>
            </joint>

            <joint type="revolute" name="right_back_wheel_hinge">
                <pose>0 0 0.03 0 0 0</pose>
                <child>right_back_wheel</child>
                <parent>chassis</parent>
                <axis>
                    <xyz>0 0 1</xyz>
                </axis>
            </joint>

            <plugin name="lidar_control" filename="liblidar_plugin.so">
                <!-- <velocity>5</velocity> -->
            </plugin>
        </model>
    </world>
</sdf>